<sdf version='1.7'>
  <model name='vmegarover'>
    <link name='base_footprint'>
      <inertial>
        <pose>-0.058504 0 -0.000385 0 -0 0</pose>
        <mass>13.972</mass>
        <inertia>
          <ixx>0.113046</ixx>
          <ixy>0</ixy>
          <ixz>-0.00355375</ixz>
          <iyy>0.208553</iyy>
          <iyz>0</iyz>
          <izz>0.275132</izz>
        </inertia>
      </inertial>
      <collision name='base_footprint_fixed_joint_lump__base_link_collision'>
        <pose>0 0 0 0 -0 0</pose>
        <geometry>
          <mesh>
            <scale>1 1 1</scale>
            <uri>model://vmegarover/meshes/stl/vmega_body.stl</uri>
          </mesh>
        </geometry>
        <surface>
          <contact>
            <ode/>
          </contact>
          <friction>
            <ode>
              <mu>0</mu>
              <mu2>0</mu2>
            </ode>
          </friction>
        </surface>
      </collision>
      <collision name='base_footprint_fixed_joint_lump__front_lrf_link_collision_1'>
        <pose>0.099 0 0.1015 0 -0 0</pose>
        <geometry>
          <mesh>
            <scale>1 1 1</scale>
            <uri>model://vmegarover/meshes/stl/lrf.stl</uri>
          </mesh>
        </geometry>
        <surface>
          <contact>
            <ode/>
          </contact>
          <friction>
            <ode/>
          </friction>
        </surface>
      </collision>
      <visual name='base_footprint_fixed_joint_lump__base_link_visual'>
        <pose>0 0 0 0 -0 0</pose>
        <geometry>
          <mesh>
            <scale>1 1 1</scale>
            <uri>model://vmegarover/meshes/dae/vmega_body.dae</uri>
          </mesh>
        </geometry>
      </visual>
      <visual name='base_footprint_fixed_joint_lump__front_lrf_link_visual_1'>
        <pose>0.099 0 0.1015 0 -0 0</pose>
        <geometry>
          <mesh>
            <scale>1 1 1</scale>
            <uri>model://vmegarover/meshes/dae/lrf.dae</uri>
          </mesh>
        </geometry>
      </visual>
      <velocity_decay/>
      <self_collide>0</self_collide>
      <gravity>1</gravity>
      <velocity_decay/>
      <sensor name='front_lrf_sensor' type='ray'>
        <visualize>1</visualize>
        <update_rate>40</update_rate>
        <ray>
          <scan>
            <horizontal>
              <samples>1000</samples>
              <resolution>1</resolution>
              <min_angle>-1.57</min_angle>
              <max_angle>1.57</max_angle>
            </horizontal>
          </scan>
          <range>
            <min>0.06</min>
            <max>4</max>
            <resolution>0.001</resolution>
          </range>
          <noise>
            <type>gaussian</type>
            <mean>0</mean>
            <stddev>0.03</stddev>
          </noise>
        </ray>
        <plugin name='gazebo_ros_front_lrf_controller' filename='libgazebo_ros_ray_sensor.so'>
          <ros>
            <remapping>~/out:=scan</remapping>
          </ros>
          <output_type>sensor_msgs/LaserScan</output_type>
          <frame_name>front_lrf_link</frame_name>
        </plugin>
        <pose>0.099 0 0.1015 0 -0 0</pose>
      </sensor>
    </link>
    <joint name='left_wheel_joint' type='revolute'>
      <pose relative_to='base_footprint'>0 0.14199 0.074742 0 0 -3.14159</pose>
      <parent>base_footprint</parent>
      <child>left_wheel_link</child>
      <axis>
        <xyz>0 -1 0</xyz>
        <limit>
          <lower>-1e+16</lower>
          <upper>1e+16</upper>
        </limit>
        <dynamics>
          <spring_reference>0</spring_reference>
          <spring_stiffness>0</spring_stiffness>
        </dynamics>
      </axis>
    </joint>
    <link name='left_wheel_link'>
      <pose relative_to='left_wheel_joint'>0 0 0 0 -0 0</pose>
      <inertial>
        <pose>0 0 0 -1.5708 0 0</pose>
        <mass>0.823</mass>
        <inertia>
          <ixx>0.00125014</ixx>
          <ixy>0</ixy>
          <ixz>0</ixz>
          <iyy>0.00125014</iyy>
          <iyz>0</iyz>
          <izz>0.00237682</izz>
        </inertia>
      </inertial>
      <collision name='left_wheel_link_collision'>
        <pose>0 0 0 -1.5708 0 0</pose>
        <geometry>
          <cylinder>
            <length>0.03</length>
            <radius>0.076</radius>
          </cylinder>
        </geometry>
        <surface>
          <contact>
            <ode/>
          </contact>
          <friction>
            <ode>
              <mu>1</mu>
              <mu2>1</mu2>
            </ode>
          </friction>
        </surface>
      </collision>
      <visual name='left_wheel_link_visual'>
        <pose>0 0 0 0 -0 0</pose>
        <geometry>
          <mesh>
            <scale>1 1 1</scale>
            <uri>model://vmegarover/meshes/dae/vmega_wheel.dae</uri>
          </mesh>
        </geometry>
      </visual>
      <gravity>1</gravity>
      <velocity_decay/>
      <self_collide>0</self_collide>
    </link>
    <joint name='right_wheel_joint' type='revolute'>
      <pose relative_to='base_footprint'>0 -0.14199 0.074742 0 -0 0</pose>
      <parent>base_footprint</parent>
      <child>right_wheel_link</child>
      <axis>
        <xyz>0 1 0</xyz>
        <limit>
          <lower>-1e+16</lower>
          <upper>1e+16</upper>
        </limit>
        <dynamics>
          <spring_reference>0</spring_reference>
          <spring_stiffness>0</spring_stiffness>
        </dynamics>
      </axis>
    </joint>
    <link name='right_wheel_link'>
      <pose relative_to='right_wheel_joint'>0 0 0 0 -0 0</pose>
      <inertial>
        <pose>0 0 0 -1.5708 0 0</pose>
        <mass>0.823</mass>
        <inertia>
          <ixx>0.00125014</ixx>
          <ixy>0</ixy>
          <ixz>0</ixz>
          <iyy>0.00125014</iyy>
          <iyz>0</iyz>
          <izz>0.00237682</izz>
        </inertia>
      </inertial>
      <collision name='right_wheel_link_collision'>
        <pose>0 0 0 -1.5708 0 0</pose>
        <geometry>
          <cylinder>
            <length>0.03</length>
            <radius>0.076</radius>
          </cylinder>
        </geometry>
        <surface>
          <contact>
            <ode/>
          </contact>
          <friction>
            <ode>
              <mu>1</mu>
              <mu2>1</mu2>
            </ode>
          </friction>
        </surface>
      </collision>
      <visual name='right_wheel_link_visual'>
        <pose>0 0 0 0 -0 0</pose>
        <geometry>
          <mesh>
            <scale>1 1 1</scale>
            <uri>model://vmegarover/meshes/dae/vmega_wheel.dae</uri>
          </mesh>
        </geometry>
      </visual>
      <gravity>1</gravity>
      <velocity_decay/>
      <self_collide>0</self_collide>
    </link>
    <static>0</static>

    <plugin name='diff_drive' filename='libgazebo_ros_diff_drive.so'>
      <ros>
      </ros>

      <update_rate>50</update_rate>
      <left_joint>left_wheel_joint</left_joint>
      <right_joint>right_wheel_joint</right_joint>

      <wheel_separation>0.313982</wheel_separation>
      <wheel_diameter>0.152</wheel_diameter>

      <publish_odom>true</publish_odom>
      <publish_odom_tf>true</publish_odom_tf>

      <odometry_frame>odom</odometry_frame>
      <robot_base_frame>base_footprint</robot_base_frame>
    </plugin>
  </model>
</sdf>
